<robot name="2dof" version="1.0">
  <link name="base_link">
    <inertial>
      <origin xyz="0 0 0" rpy="0 0 0" />
      <mass value="1.0" />
      <inertia ixx="1e-06" ixy="0" ixz="0" iyy="1e-06" iyz="0" izz="1e-06" />
    </inertial>
  </link>
  <link name="link_1">
    <inertial>
      <origin xyz="1 0 0" rpy="0 0 0" />
      <mass value="2.0" />
      <inertia ixx="1" ixy="0" ixz="0" iyy="1" iyz="0" izz="1" />
    </inertial>
  </link>
  <joint name="joint_1" type="continuous">
    <origin xyz="1 0 0" rpy="0 0 0" />
    <parent link="base_link" />
    <child link="link_1" />
    <axis xyz="0 1 0" />
  </joint>
  <link name="link_2">
    <inertial>
      <origin xyz="1 0 0" rpy="0 0 0" />
      <mass value="2.0" />
      <inertia ixx="1" ixy="0" ixz="0" iyy="1" iyz="0" izz="1" />
    </inertial>
  </link>
  <joint name="joint_2" type="continuous">
    <origin xyz="1 0 0" rpy="0 0 0" />
    <parent link="link_1" />
    <child link="link_2" />
    <axis xyz="0 1 0" />
  </joint>
</robot>
